Workbook

Sheet Consolidado
A1: Autenticación | B1: =+'Desarollo Modulos Cliente'!B1 -> 1 | D1: =AVERAGE(B1,B2,B7,B12,B16,B23,B37,B46,B49,B52) -> 0.85461538
A2: Performance | B2: =+'Desarollo Modulos Cliente'!B5 -> 1
A3: ICO, ICP, Performance de la Compañia | B3: =+'Desarollo Modulos Cliente'!B6 -> 1
A4: Grafico Posiciones | B4: =+'Desarollo Modulos Cliente'!B7 -> 1
A5: Grafico Mapa de Performance | B5: =+'Desarollo Modulos Cliente'!B8 -> 1
A6: Resumen Posiciones | B6: =+'Desarollo Modulos Cliente'!B9 -> 1
A7: Plan Estrategico | B7: =AVERAGE(B8:B11) -> 1
A8: Tab Definicion | B8: =+'Desarollo Modulos Cliente'!B16 -> 1
A9: Tab Mapa Estrategico | B9: =+'Desarollo Modulos Cliente'!B24 -> 1
A10: Filtros | B10: =+'Desarollo Modulos Cliente'!B31 -> 1
A11: Plan Estrategico | B11: =+'Desarollo Modulos Cliente'!B143 -> 1
A12: Posiciones | B12: =+'Desarollo Modulos Cliente'!B33 -> 0.9375
A13: Tab Definicion | B13: =+'Desarollo Modulos Cliente'!B34 -> 1
A14: Tab Organigrama | B14: =+'Desarollo Modulos Cliente'!B40 -> 0.8125
A15: Filtros | B15: =+'Desarollo Modulos Cliente'!B49 -> 1
A16: Proyectos Estrategicos | B16: =+AVERAGE(B17:B22) -> 0.97916667
A17: Visualizacion Tarjetas Resumen | B17: =+'Desarollo Modulos Cliente'!B55 -> 1
A18: Visualizacion Tarjetas Proyectos | B18: =+'Desarollo Modulos Cliente'!B60 -> 1
A19: Funcionalidades Pantalla | B19: =+'Desarollo Modulos Cliente'!B72 -> 1
A20: Formularios/Modales | B20: =+'Desarollo Modulos Cliente'!B76 -> 0.875
A21: Filtros | B21: =+'Desarollo Modulos Cliente'!B81 -> 1
A22: Reporteria | B22: =+'Desarollo Modulos Cliente'!B144 -> 1
A23: Objetivos | B23: =AVERAGE(B24:B36) -> 0.97948718
A24: Tab Tablero ICO | B24: =+'Desarollo Modulos Cliente'!B85 -> 0.93333333
A25: Visualizacion Tarjetas Resumen | B25: =+'Desarollo Modulos Cliente'!B86 -> 1
A26: Tablero ICO | B26: =+'Desarollo Modulos Cliente'!B90 -> 0.8
A27: Tendencia Anual | B27: =+'Desarollo Modulos Cliente'!B96 -> 1
A28: Tab Cumplimiento | B28: =+'Desarollo Modulos Cliente'!B97 -> 1
A29: Tabla cumplimiento de objetivos | B29: =+'Desarollo Modulos Cliente'!B98 -> 1
A30: Tabla objetivos sin configurar | B30: =+'Desarollo Modulos Cliente'!B101 -> 1
A31: Funcionalidades Pantalla | B31: =+'Desarollo Modulos Cliente'!B104 -> 1
A32: Formularios/Modales | B32: =+'Desarollo Modulos Cliente'!B107 -> 1
A33: Construccion del mapa Estrategico | B33: =+'Desarollo Modulos Cliente'!B112 -> 1
A34: Filtros | B34: =+'Desarollo Modulos Cliente'!B113 -> 1
A35: Notas | B35: =+'Desarollo Modulos Cliente'!B137 -> 1
A36: Carga de Documentos | B36: =+'Desarollo Modulos Cliente'!B140 -> 1
A37: Prioridades | B37: =AVERAGE(B38:B45) -> 1
A38: Visualizacion | B38: =+'Desarollo Modulos Cliente'!B119 -> 1
A39: Tabla Prioridades | B39: =+'Desarollo Modulos Cliente'!B124 -> 1
A40: Funcionalidades Pantalla | B40: =+'Desarollo Modulos Cliente'!B127 -> 1
...

Sheet Permisos
B2: Permisos
B4: Modulo Plan estrategico
B5: Pestaña Definicion
B6: Rol | C6: Leer | D6: Crear | E6: Actualizar | F6: Eliminar/Borrar | G6: Ordenar | H6: Filtro | I6: Generar reporte
B7: Especialista | C7: SI | D7: SI | E7: SI | F7: SI | G7: SI | H7: Todos | I7: SI
B8: Cliente | C8: SI | D8: NO | E8: NO | F8: NO | G8: NO | H8: Todos | I8: SI
B10: Pestaña Mapa estrategico
B11: Rol | C11: Leer | D11: Crear | E11: Actualizar | F11: Eliminar/Borrar | G11: Ordenar | H11: Filtro Posicion
B12: Especialista | C12: SI | D12: N/A | E12: N/A | F12: N/A | G12: N/A | H12: Todos
B13: Cliente | C13: SI | D13: N/A | E13: N/A | F13: N/A | G13: N/A | H13: Todos
B15: Modulo Posisiones
B16: Pestaña Definicion
B17: Rol | C17: Leer | D17: Crear | E17: Actualizar | F17: Eliminar/Borrar | G17: Ordenar | H17: Filtro Posicion | I17: Generar reporte
B18: Especialista | C18: SI | D18: SI | E18: SI | F18: SI | G18: SI | H18: Todos | I18: SI
B19: Cliente | C19: SI | D19: NO | E19: NO | F19: NO | G19: SI | H19: Propio | I19: SI
B21: Pestaña Organigrama
B22: Rol | C22: Leer | D22: Crear | E22: Actualizar | F22: Eliminar/Borrar | G22: Ordenar | H22: Filtro Posicion | I22: ICP | J22: ICO | K22: Proyectos
B23: Especialista | C23: SI | D23: N/A | E23: N/A | F23: N/A | G23: N/A | H23: Todos | I23: SI | J23: SI | K23: SI
B24: Cliente | C24: SI Solo el propio | D24: N/A | E24: N/A | F24: N/A | G24: N/A | H24: Todos | I24: NO | J24: NO | K24: NO
B26: Modulo Proyectos
B27: Rol | C27: Leer | D27: Crear | E27: Actualizar | F27: Eliminar/Borrar | G27: Ordenar | H27: Filtro Posicion | I27: Generar reporte
B28: Especialista | C28: SI | D28: SI | E28: SI | F28: SI | G28: SI | H28: Todos | I28: SI
B29: Cliente | C29: SI | D29: SI | E29: SI | F29: NO | G29: SI | H29: Propio | I29: SI
B31: Modulo Objetivos
B32: Pestaña Tablero ICO
B33: Rol | C33: Leer | D33: Crear | E33: Actualizar | F33: Eliminar/Borrar | G33: Ordenar | H33: Filtro Posicion
B34: Especialista | C34: SI | D34: N/A | E34: N/A | F34: N/A | G34: N/A | H34: Todos
B35: Cliente | C35: SI | D35: N/A | E35: N/A | F35: N/A | G35: N/A | H35: Propio
B37: Pestaña Cumplimiento | I37: Acciones
B38: Rol | C38: Leer | D38: Crear | E38: Actualizar | F38: Eliminar/Borrar | G38: Ordenar | H38: Filtro Posicion | I38: Cumlimiento | J38: Notas | K38: Documento | L38: Configuracion | M38: Inactivar
B39: Especialista | C39: SI | D39: SI | E39: SI | F39: SI | G39: SI | H39: Todos | I39: SI | J39: SI | K39: SI | L39: SI | M39: SI
B40: Cliente | C40: SI | D40: NO | E40: NO | F40: NO | G40: SI | H40: Propio | I40: SI | J40: SI | K40: SI | L40: NO | M40: NO
B42: Modulo Prioridades | J42: Acciones
B43: Rol | C43: Leer | D43: Crear | E43: Actualizar | F43: Eliminar/Borrar | G43: Ordenar | H43: Filtro Posicion | I43: Generar reporte | J43: Editar | K43: Notas | L43: Documento | M43: Inactivar
B44: Especialista | C44: SI | D44: SI | E44: SI | F44: SI | G44: SI | H44: Todos | I44: SI | J44: SI | K44: SI | L44: SI | M44: SI
B45: Cliente | C45: SI | D45: SI | E45: SI | F45: NO | G45: SI | H45: Propio | I45: SI | J45: SI, menos la fecha de terminado | K45: SI | L45: SI | M45: NO

Sheet Desarollo Modulos Cliente
A1: Autenticación | B1: =AVERAGE(B2:B4) -> 1
A2: Inicio de Sesion | B2: 1
A3: Recuperar Contraseña | B3: 1
A4: Confirmacion de Correo | B4: 1
A5: Performance | B5: =AVERAGE(B6:B10) -> 1
A6: ICO, ICP, Performance de la Compañia | B6: 1
A7: Grafico Posiciones | B7: 1
A8: Grafico Mapa de Performance | B8: 1
A9: Resumen Posiciones | B9: 1
A10: Filtros | B10: =AVERAGE(B11:B14,B18) -> 1
A11: Plan | B11: 1
A12: Posicion | B12: 1
A13: Mes | B13: 1
A14: Año | B14: 1
A15: Plan Estrategico | B15: =AVERAGE(B16,B24,B31) -> 1
A16: Tab Definicion | B16: =AVERAGE(B17:B23,B26) -> 1 | C16: Leer | D16: Crear | E16: Actualizar | F16: Eliminar/Borrar | G16: Ordenar
A17: Tarjeta Mision | B17: =AVERAGE(C17:G17) -> 1 | C17: 1 | D17: No Aplica | E17: 1 | F17: No Aplica | G17: No Aplica
A18: Tarjeta Vision | B18: =AVERAGE(C18:G18) -> 1 | C18: 1 | D18: No Aplica | E18: 1 | F18: No Aplica | G18: No Aplica
A19: Tarjeta Ventaja Distintiva | B19: =AVERAGE(C19:G19) -> 1 | C19: 1 | D19: No Aplica | E19: 1 | F19: No Aplica | G19: No Aplica
A20: Tarjeta Factores Clave de Éxito | B20: =AVERAGE(C20:G20) -> 1 | C20: 1 | D20: 1 | E20: 1 | F20: 1 | G20: 1
A21: Tarjeta Valores | B21: =AVERAGE(C21:G21) -> 1 | C21: 1 | D21: 1 | E21: 1 | F21: 1 | G21: 1
A22: Tarjeta Objetivos CEO | B22: =AVERAGE(C22:G22) -> 1 | C22: 1 | D22: 1 | E22: 1 | F22: 1 | G22: 1
A23: Tarjeta Proyectos Estrategicos CEO | B23: =AVERAGE(C23:G23) -> 1 | C23: 1 | D23: 1 | E23: 1 | F23: 1 | G23: 1
A24: Tab Mapa Estrategico | B24: =AVERAGE(B25:B30,B34) -> 1
A25: Visualizacion Perspectiva Financiera | B25: 1
A26: Visualizacion Perspectiva Cliente | B26: 1
A27: Visualizacion Perspectiva Procesos | B27: 1
A28: Visualizacion Perspectiva Persona | B28: 1
A29: Opciones de Zoom y Bloqueo | B29: 1
A30: =A109 -> Campos de Mapa Estrategico: Selector de Nivel, Selector de Orientacion, Selector de Perspectiva, Selector Objetivos al que impacta, Estado del Objetivo | B30: 1
A31: Filtros | B31: =AVERAGE(B32) -> 1
A32: Plan | B32: 1
A33: Posiciones | B33: =AVERAGE(B34,B40,B49) -> 0.9375
A34: Tab Definicion | B34: =AVERAGE(B35:B39) -> 1 | C34: Leer | D34: Crear | E34: Actualizar | F34: Eliminar/Borrar | G34: Ordenar
A35: Tarjeta Mision | B35: =AVERAGE(C35:G35) -> 1 | C35: 1 | D35: No Aplica | E35: 1 | F35: 1 | G35: 1
A36: Tarjeta Vision | B36: =AVERAGE(C36:G36) -> 1 | C36: 1 | D36: No Aplica | E36: 1 | F36: 1 | G36: 1
A37: Tarjeta Objetivos | B37: =AVERAGE(C37:G37) -> 1 | C37: 1 | D37: 1 | E37: 1 | F37: 1 | G37: 1
A38: Tarjeta Proyectos Estrategicos | B38: =AVERAGE(C38:G38) -> 1 | C38: 1 | D38: 1 | E38: 1 | F38: 1 | G38: 1
A39: Tarjeta Palancas | B39: =AVERAGE(C39:G39) -> 1 | C39: 1 | D39: 1 | E39: 1 | F39: 1 | G39: 1
A40: Tab Organigrama | B40: =AVERAGE(B41:B48) -> 0.8125
...

Sheet Desarrollos Modulos Admin
A1: Descripcion Modulo/Funcionalidad | B1: =AVERAGE(B2,B8) -> 1 | C1: Leer | D1: Crear | E1: Actualizar | F1: Eliminar/Borrar | G1: Cargar Imagen | H1: Adjuntar Documento | I1: Crear Nota
A2: Modulos Configuracion | B2: =AVERAGE(B3:B7) -> 1
A3: Compañias | B3: =AVERAGE(C3:H3) -> 1 | C3: 1 | D3: 1 | E3: 1 | F3: 1 | G3: 1 | H3: 1 | I3: No Aplica
A4: Unidades de Negocio | B4: =AVERAGE(C4:H4) -> 1 | C4: 1 | D4: 1 | E4: 1 | F4: 1 | G4: 1 | H4: 1 | I4: No Aplica
A5: Usuarios | B5: =AVERAGE(C5:H5) -> 1 | C5: 1 | D5: 1 | E5: 1 | F5: 1 | G5: 1 | H5: No Aplica | I5: No Aplica
A6: Posiciones | B6: =AVERAGE(C6:H6) -> 1 | C6: 1 | D6: 1 | E6: 1 | F6: 1 | G6: No Aplica | H6: No Aplica | I6: No Aplica
A7: Plan Estrategico | B7: =AVERAGE(C7:H7) -> 1 | C7: 1 | D7: 1 | E7: 1 | F7: 1 | G7: No Aplica | H7: No Aplica | I7: No Aplica
A8: Formularios/Modales | B8: =AVERAGE(B9:B14) -> 1
A9: Campos de Compañia: Nombre, Identificacion, Descripcion, Representante legal, Telefono, Direccion | B9: 1
A10: Campos de Unidad de Negocio: Nombre, Identificacion, Representante legal, Telefono, Direccion, Descripcion, Selector Compañía | B10: 1
A11: Campos de Usuarios: Nombre, Apellido, Correo, Identificacion, Telefono, Selector del Rol, Selector Unida de Negocio | B11: 1
A12: Asignacion de Permisos Personalizados | B12: 1
A13: Campos Posicion: Nombre, Selector Unidad de Negocio, Selector Usuario asignado, Selector Posicion Superior, Check Es CEO | B13: 1
A14: Campos Plan Estrategico: Nombre, Selector Unidad de Negocio, Selector Fecha Inicio, Selector Fecha Fina, Descripcion | B14: 1

Sheet Implementacion PONCE3
A1: Migracion Base de Datos PONCE3 | B1: =AVERAGE(B2:B21) -> 1 | D1: Modulos / Funcionalidades SOE Implementadas en PONCE3 | E1: =AVERAGE(E2,E6,E12,E16,E20,E24,E31,E33,E36,E39,E43,E46,E49) -> 0.83974359 | G1: Modulos / Funcionalidades SOE Admin | H1: =AVERAGE(H2,H5,H9,H18,H22) -> 1
A2: Compañias | B2: 1 | D2: Autenticación | E2: =AVERAGE(E3:E5) -> 1 | G2: Compañias | H2: =AVERAGE(H3:H4) -> 1
A3: Creacion de Unidades de Negocio | B3: 1 | D3: Inicio de Sesion | E3: 1 | G3: Creacion, Edicion, Inactivacion, Lista | H3: 1
A4: Usuarios | B4: 1 | D4: Recuperar Contraseña | E4: 1 | G4: Adjuntar Documento | H4: 1
A5: Planes Estrategicos | B5: 1 | D5: Confirmacion de Correo | E5: 1 | G5: Unidades de Negocio | H5: =AVERAGE(H6:H8) -> 1
A6: Factores Claves de Exito | B6: 1 | D6: Performance | E6: =AVERAGE(E7:E11) -> 1 | G6: Creacion, Edicion, Inactivacion, Lista | H6: 1
A7: Valores | B7: 1 | D7: Filtros: Plan, Posicion, Mes, Año | E7: 1 | G7: Asignacion de Compañia | H7: 1
A8: Posiciones | B8: 1 | D8: ICO, ICP, Performance de la Compañia | E8: 1 | G8: Adjuntar Documento | H8: 1
A9: Palancas | B9: 1 | D9: Grafico Posiciones | E9: 1 | G9: Usuarios | H9: =AVERAGE(H10:H17) -> 1
A10: Asignacion de Usuarios con Posiciones en Unidades de Negocio | B10: 1 | D10: Grafico Mapa de Performance | E10: 1 | G10: Creacion, Edicion, Inactivacion, Lista | H10: 1
A11: Proyectos Estrategicos | B11: 1 | D11: Resumen Posiciones | E11: 1 | G11: Restablecer Contraseña | H11: 1
A12: Factores Claves de Exito | B12: 1 | D12: Plan Estrategico | E12: =AVERAGE(E13:E15) -> 0.83333333 | G12: Enviar mail de confirmacion | H12: 1
A13: Tareas | B13: 1 | D13: Filtros: Plan | E13: 1 | G13: Asignar Rol | H13: 1
A14: Participante por defecto del proyecto | B14: 1 | D14: Definicion | E14: 1 | G14: Asignar Unidad de Negocio | H14: 1
A15: Objetivos | B15: 1 | D15: Mapa Estrategico | E15: 0.5 | G15: Cambiar de unidad de Negocio | H15: 1
A16: Indicadores | B16: 1 | D16: Posiciones | E16: =AVERAGE(E17:E19) -> 1 | G16: Asignar Permisos Personalizados | H16: 1
A17: Cumplimiento de Objetivos | B17: 1 | D17: Filtros: Plan, Posicion, Mes, Año | E17: 1 | G17: Cargar Foto de Perfil | H17: 1
A18: Prioridades | B18: 1 | D18: Definicion | E18: 1 | G18: Posiciones | H18: =AVERAGE(H19:H21) -> 1
A19: Asignacion de Roles | B19: 1 | D19: Organigrama | E19: 1 | G19: Creacion, Edicion, Inactivacion, Lista | H19: 1
A20: Asignacion de Permisos del Sistema | B20: 1 | D20: Proyectos Estrategico | E20: =AVERAGE(E21:E23) -> 1 | G20: Asignar a Usuario | H20: 1
A21: Notas de Usuarios | B21: 1 | D21: Filtros: Plan, Posicion | E21: 1 | G21: Establecer posicion superior | H21: 1
D22: Factores | E22: 1 | G22: Plan Estrategico | H22: =AVERAGE(H23) -> 1
D23: Tarea | E23: 1 | G23: Creacion, Edicion, Inactivacion, Lista | H23: 1
D24: Objetivos | E24: =AVERAGE(E25:E30) -> 1
D25: Filtros: Plan, Posicion, Año | E25: 1
D26: Tablero ICO | E26: 1
D27: Cumplimiento de Objetivos | E27: 1
D28: Ajuste de Meta | E28: 1
D29: Configuracion de Indicador | E29: 1
D30: Construccion del mapa Estrategico | E30: 1
D31: Prioridades | E31: =AVERAGE(E32) -> 1
D32: Filtros: Plan, Posicion, Mes, Año | E32: 1
D33: Notas | E33: =AVERAGE(E34:E35) -> 1
D34: Objetivos | E34: 1
D35: Prioridades | E35: 1
D36: Carga de Documentos | E36: =AVERAGE(E37:E38) -> 1
D37: Objetivos | E37: 1
D38: Prioridades | E38: 1
D39: Reporteria | E39: =AVERAGE(E40:E42) -> 0.83333333
D40: Plan Estrategico | E40: 1
...

Sheet Dominio
A1: DESCRIPCION | B1: LINK | C1: PUERTO
A2: Soe v1 | B2: qa.soe.la | C2: 4002
A3: Soe v1 API | B3: api.soe.la | C3: 5000
A5: Soe v2 | B5: portal.soe.la | C5: 3000
A6: Soe v2 API | B6: api-qav2.soe.la | C6: 4022
A8: Demo Soe v2 | B8: demov2.soe.la | C8: 3032
A9: Demo Soe v2 API | B9: api-demov2.soe.la | C9: 4032
A11: Reporteria | B11: api-report-qa.soe.la | C11: 8090
